Workbook

Sheet Session Generator
B2: Badminton — Standalone Session Test Data Generator
B3: 75 standalone-session test cases (15 per hour slot × 5 hour slots: 07:00, 11:00, 15:00, 19:00, 23:00) for the date entered below. Every formula recalculates automatically the moment you change the date — no macro, no button to click.
B5: Session date (input): | C5: =TODAY()+1 | D5: <- edit this cell (yellow). Every row below recalculates instantly.
B7: AUTO-UPDATES ON DATE CHANGE — no "Generate" button needed (see Read Me tab for why). Rows are grouped by hour (± buttons in the left margin) — collapse a group to skim faster.
B9: # | C9: Hour slot | D9: Title (session case) | E9: Scheduled Start — local (display) | F9: scheduledStart — API payload (offset-aware ISO) | G9: sportId | H9: sportName | I9: locationId | J9: locationName | K9: capacity | L9: feeType | M9: feeAmountVnd | N9: autoApprove | O9: isPublic (after create via API) | P9: Manual DB fix needed? | Q9: Post-creation SQL (dev DB only) | R9: Purpose / what this case covers | S9: Author email (createdBy) | T9: Author userId (must be the authenticated caller)
B10: 1 | C10: 7 | D10: Free · Open-join · Tin Sport | E10: =$C$5+TIME(C10,0,0) | F10: =TEXT($C$5,"yyyy-mm-dd")&"T"&TEXT(C10,"00")&":00:00+07:00" | G10: 1 | H10: Badminton | I10: 7 | J10: Tin sport Badminton (Sân cầu lông) | K10: 10 | L10: FREE | N10: TRUE | O10: TRUE | P10: No | R10: Covers feeType=FREE + autoApprove=true (open-join). | S10: bao.mmo7@gmail.com | T10: d6e7ba31-23fa-4359-a736-e706db8284c2
B11: 2 | C11: 7 | D11: Free · Open-join · Trọng Nghĩa | E11: =$C$5+TIME(C11,0,0) | F11: =TEXT($C$5,"yyyy-mm-dd")&"T"&TEXT(C11,"00")&":00:00+07:00" | G11: 1 | H11: Badminton | I11: 10 | J11: Sân Cầu Lông Trọng Nghĩa | K11: 10 | L11: FREE | N11: TRUE | O11: TRUE | P11: No | R11: Covers feeType=FREE + autoApprove=true (open-join). | S11: bao.mmo4@gmail.com | T11: 6c282544-57b6-4712-bb6a-bc696a4ee09b
B12: 3 | C12: 7 | D12: Free · Approval-required · Tin Sport | E12: =$C$5+TIME(C12,0,0) | F12: =TEXT($C$5,"yyyy-mm-dd")&"T"&TEXT(C12,"00")&":00:00+07:00" | G12: 1 | H12: Badminton | I12: 7 | J12: Tin sport Badminton (Sân cầu lông) | K12: 10 | L12: FREE | N12: FALSE | O12: TRUE | P12: No | R12: Covers feeType=FREE + autoApprove=false (REQUESTED, awaiting approval). | S12: bao.mmo3@gmail.com | T12: a4989bbe-033a-4a20-9784-7dafe8a7829e
B13: 4 | C13: 7 | D13: Free · Approval-required · Trọng Nghĩa | E13: =$C$5+TIME(C13,0,0) | F13: =TEXT($C$5,"yyyy-mm-dd")&"T"&TEXT(C13,"00")&":00:00+07:00" | G13: 1 | H13: Badminton | I13: 10 | J13: Sân Cầu Lông Trọng Nghĩa | K13: 10 | L13: FREE | N13: FALSE | O13: TRUE | P13: No | R13: Covers feeType=FREE + autoApprove=false (REQUESTED, awaiting approval). | S13: bao.mmo3@gmail.com | T13: a4989bbe-033a-4a20-9784-7dafe8a7829e
B14: 5 | C14: 7 | D14: Split-cost · Open-join · Tin Sport | E14: =$C$5+TIME(C14,0,0) | F14: =TEXT($C$5,"yyyy-mm-dd")&"T"&TEXT(C14,"00")&":00:00+07:00" | G14: 1 | H14: Badminton | I14: 7 | J14: Tin sport Badminton (Sân cầu lông) | K14: 6 | L14: SPLIT | N14: TRUE | O14: TRUE | P14: No | R14: Covers feeType=SPLIT + autoApprove=true (open-join). | S14: bao.mmo6@gmail.com | T14: ebc9e657-541e-4239-b32a-feb3cab1d6c7
B15: 6 | C15: 7 | D15: Split-cost · Open-join · Trọng Nghĩa | E15: =$C$5+TIME(C15,0,0) | F15: =TEXT($C$5,"yyyy-mm-dd")&"T"&TEXT(C15,"00")&":00:00+07:00" | G15: 1 | H15: Badminton | I15: 10 | J15: Sân Cầu Lông Trọng Nghĩa | K15: 6 | L15: SPLIT | N15: TRUE | O15: TRUE | P15: No | R15: Covers feeType=SPLIT + autoApprove=true (open-join). | S15: bao.mmo3@gmail.com | T15: a4989bbe-033a-4a20-9784-7dafe8a7829e
B16: 7 | C16: 7 | D16: Split-cost · Approval-required · Tin Sport | E16: =$C$5+TIME(C16,0,0) | F16: =TEXT($C$5,"yyyy-mm-dd")&"T"&TEXT(C16,"00")&":00:00+07:00" | G16: 1 | H16: Badminton | I16: 7 | J16: Tin sport Badminton (Sân cầu lông) | K16: 6 | L16: SPLIT | N16: FALSE | O16: TRUE | P16: No | R16: Covers feeType=SPLIT + autoApprove=false (REQUESTED, awaiting approval). | S16: bao.mmo5@gmail.com | T16: 456f3ac4-98f3-43d0-9b7a-7b3bd0c886ac
B17: 8 | C17: 7 | D17: Split-cost · Approval-required · Trọng Nghĩa | E17: =$C$5+TIME(C17,0,0) | F17: =TEXT($C$5,"yyyy-mm-dd")&"T"&TEXT(C17,"00")&":00:00+07:00" | G17: 1 | H17: Badminton | I17: 10 | J17: Sân Cầu Lông Trọng Nghĩa | K17: 6 | L17: SPLIT | N17: FALSE | O17: TRUE | P17: No | R17: Covers feeType=SPLIT + autoApprove=false (REQUESTED, awaiting approval). | S17: bao.mmo7@gmail.com | T17: d6e7ba31-23fa-4359-a736-e706db8284c2
B18: 9 | C18: 7 | D18: Fixed fee (50k) · Open-join · Tin Sport | E18: =$C$5+TIME(C18,0,0) | F18: =TEXT($C$5,"yyyy-mm-dd")&"T"&TEXT(C18,"00")&":00:00+07:00" | G18: 1 | H18: Badminton | I18: 7 | J18: Tin sport Badminton (Sân cầu lông) | K18: 8 | L18: FIXED | M18: 50000 | N18: TRUE | O18: TRUE | P18: No | R18: Covers feeType=FIXED + autoApprove=true (open-join). | S18: bao.mmo7@gmail.com | T18: d6e7ba31-23fa-4359-a736-e706db8284c2
B19: 10 | C19: 7 | D19: Fixed fee (70k) · Open-join · Trọng Nghĩa | E19: =$C$5+TIME(C19,0,0) | F19: =TEXT($C$5,"yyyy-mm-dd")&"T"&TEXT(C19,"00")&":00:00+07:00" | G19: 1 | H19: Badminton | I19: 10 | J19: Sân Cầu Lông Trọng Nghĩa | K19: 8 | L19: FIXED | M19: 70000 | N19: TRUE | O19: TRUE | P19: No | R19: Covers feeType=FIXED + autoApprove=true (open-join). | S19: bao.mmo7@gmail.com | T19: d6e7ba31-23fa-4359-a736-e706db8284c2
B20: 11 | C20: 7 | D20: Fixed fee (50k) · Approval-required · Tin Sport | E20: =$C$5+TIME(C20,0,0) | F20: =TEXT($C$5,"yyyy-mm-dd")&"T"&TEXT(C20,"00")&":00:00+07:00" | G20: 1 | H20: Badminton | I20: 7 | J20: Tin sport Badminton (Sân cầu lông) | K20: 8 | L20: FIXED | M20: 50000 | N20: FALSE | O20: TRUE | P20: No | R20: Covers feeType=FIXED + autoApprove=false (REQUESTED, awaiting approval). | S20: bao.mmo5@gmail.com | T20: 456f3ac4-98f3-43d0-9b7a-7b3bd0c886ac
B21: 12 | C21: 7 | D21: Fixed fee (70k) · Approval-required · Trọng Nghĩa | E21: =$C$5+TIME(C21,0,0) | F21: =TEXT($C$5,"yyyy-mm-dd")&"T"&TEXT(C21,"00")&":00:00+07:00" | G21: 1 | H21: Badminton | I21: 10 | J21: Sân Cầu Lông Trọng Nghĩa | K21: 8 | L21: FIXED | M21: 70000 | N21: FALSE | O21: TRUE | P21: No | R21: Covers feeType=FIXED + autoApprove=false (REQUESTED, awaiting approval). | S21: bao.mmo4@gmail.com | T21: 6c282544-57b6-4712-bb6a-bc696a4ee09b
B22: 13 | C22: 7 | D22: Free · Open-join · Tin Sport (PRIVATE — manual DB fix) | E22: =$C$5+TIME(C22,0,0) | F22: =TEXT($C$5,"yyyy-mm-dd")&"T"&TEXT(C22,"00")&":00:00+07:00" | G22: 1 | H22: Badminton | I22: 7 | J22: Tin sport Badminton (Sân cầu lông) | K22: 10 | L22: FREE | N22: TRUE | O22: TRUE | P22: YES | Q22: UPDATE sessions SET is_public = false WHERE id = <fill in row #13's new session id after creating it via the app/API>; | R22: isPublic is hardcoded true for every standalone session at creation (SessionServiceImpl.java:225). Create via the API as normal, then run this row's Post-creation SQL against the dev DB to flip isPublic to false, and confirm GET /api/sessions/discover no longer returns it (SESSION-37/39's isPublic gate). | S22: bao.mmo8@gmail.com | T22: c98b95c9-df75-4be5-baa1-4892ed15044a
B23: 14 | C23: 7 | D23: Split-cost · Approval-required · Trọng Nghĩa (PRIVATE — manual DB fix) | E23: =$C$5+TIME(C23,0,0) | F23: =TEXT($C$5,"yyyy-mm-dd")&"T"&TEXT(C23,"00")&":00:00+07:00" | G23: 1 | H23: Badminton | I23: 10 | J23: Sân Cầu Lông Trọng Nghĩa | K23: 6 | L23: SPLIT | N23: FALSE | O23: TRUE | P23: YES | Q23: UPDATE sessions SET is_public = false WHERE id = <fill in row #14's new session id after creating it via the app/API>; | R23: isPublic is hardcoded true for every standalone session at creation (SessionServiceImpl.java:225). Create via the API as normal, then run this row's Post-creation SQL against the dev DB to flip isPublic to false, and confirm GET /api/sessions/discover no longer returns it (SESSION-37/39's isPublic gate). | S23: bao.mmo3@gmail.com | T23: a4989bbe-033a-4a20-9784-7dafe8a7829e
B24: 15 | C24: 7 | D24: Fixed fee (50k) · Open-join · Tin Sport (PRIVATE — manual DB fix) | E24: =$C$5+TIME(C24,0,0) | F24: =TEXT($C$5,"yyyy-mm-dd")&"T"&TEXT(C24,"00")&":00:00+07:00" | G24: 1 | H24: Badminton | I24: 7 | J24: Tin sport Badminton (Sân cầu lông) | K24: 8 | L24: FIXED | M24: 50000 | N24: TRUE | O24: TRUE | P24: YES | Q24: UPDATE sessions SET is_public = false WHERE id = <fill in row #15's new session id after creating it via the app/API>; | R24: isPublic is hardcoded true for every standalone session at creation (SessionServiceImpl.java:225). Create via the API as normal, then run this row's Post-creation SQL against the dev DB to flip isPublic to false, and confirm GET /api/sessions/discover no longer returns it (SESSION-37/39's isPublic gate). | S24: bao.mmo5@gmail.com | T24: 456f3ac4-98f3-43d0-9b7a-7b3bd0c886ac
B25: 16 | C25: 11 | D25: Free · Open-join · Tin Sport | E25: =$C$5+TIME(C25,0,0) | F25: =TEXT($C$5,"yyyy-mm-dd")&"T"&TEXT(C25,"00")&":00:00+07:00" | G25: 1 | H25: Badminton | I25: 7 | J25: Tin sport Badminton (Sân cầu lông) | K25: 10 | L25: FREE | N25: TRUE | O25: TRUE | P25: No | R25: Covers feeType=FREE + autoApprove=true (open-join). | S25: bao.mmo4@gmail.com | T25: 6c282544-57b6-4712-bb6a-bc696a4ee09b
B26: 17 | C26: 11 | D26: Free · Open-join · Trọng Nghĩa | E26: =$C$5+TIME(C26,0,0) | F26: =TEXT($C$5,"yyyy-mm-dd")&"T"&TEXT(C26,"00")&":00:00+07:00" | G26: 1 | H26: Badminton | I26: 10 | J26: Sân Cầu Lông Trọng Nghĩa | K26: 10 | L26: FREE | N26: TRUE | O26: TRUE | P26: No | R26: Covers feeType=FREE + autoApprove=true (open-join). | S26: bao.mmo5@gmail.com | T26: 456f3ac4-98f3-43d0-9b7a-7b3bd0c886ac
B27: 18 | C27: 11 | D27: Free · Approval-required · Tin Sport | E27: =$C$5+TIME(C27,0,0) | F27: =TEXT($C$5,"yyyy-mm-dd")&"T"&TEXT(C27,"00")&":00:00+07:00" | G27: 1 | H27: Badminton | I27: 7 | J27: Tin sport Badminton (Sân cầu lông) | K27: 10 | L27: FREE | N27: FALSE | O27: TRUE | P27: No | R27: Covers feeType=FREE + autoApprove=false (REQUESTED, awaiting approval). | S27: bao.mmo4@gmail.com | T27: 6c282544-57b6-4712-bb6a-bc696a4ee09b
B28: 19 | C28: 11 | D28: Free · Approval-required · Trọng Nghĩa | E28: =$C$5+TIME(C28,0,0) | F28: =TEXT($C$5,"yyyy-mm-dd")&"T"&TEXT(C28,"00")&":00:00+07:00" | G28: 1 | H28: Badminton | I28: 10 | J28: Sân Cầu Lông Trọng Nghĩa | K28: 10 | L28: FREE | N28: FALSE | O28: TRUE | P28: No | R28: Covers feeType=FREE + autoApprove=false (REQUESTED, awaiting approval). | S28: bao.mmo4@gmail.com | T28: 6c282544-57b6-4712-bb6a-bc696a4ee09b
B29: 20 | C29: 11 | D29: Split-cost · Open-join · Tin Sport | E29: =$C$5+TIME(C29,0,0) | F29: =TEXT($C$5,"yyyy-mm-dd")&"T"&TEXT(C29,"00")&":00:00+07:00" | G29: 1 | H29: Badminton | I29: 7 | J29: Tin sport Badminton (Sân cầu lông) | K29: 6 | L29: SPLIT | N29: TRUE | O29: TRUE | P29: No | R29: Covers feeType=SPLIT + autoApprove=true (open-join). | S29: bao.mmo4@gmail.com | T29: 6c282544-57b6-4712-bb6a-bc696a4ee09b
B30: 21 | C30: 11 | D30: Split-cost · Open-join · Trọng Nghĩa | E30: =$C$5+TIME(C30,0,0) | F30: =TEXT($C$5,"yyyy-mm-dd")&"T"&TEXT(C30,"00")&":00:00+07:00" | G30: 1 | H30: Badminton | I30: 10 | J30: Sân Cầu Lông Trọng Nghĩa | K30: 6 | L30: SPLIT | N30: TRUE | O30: TRUE | P30: No | R30: Covers feeType=SPLIT + autoApprove=true (open-join). | S30: bao.mmo5@gmail.com | T30: 456f3ac4-98f3-43d0-9b7a-7b3bd0c886ac
B31: 22 | C31: 11 | D31: Split-cost · Approval-required · Tin Sport | E31: =$C$5+TIME(C31,0,0) | F31: =TEXT($C$5,"yyyy-mm-dd")&"T"&TEXT(C31,"00")&":00:00+07:00" | G31: 1 | H31: Badminton | I31: 7 | J31: Tin sport Badminton (Sân cầu lông) | K31: 6 | L31: SPLIT | N31: FALSE | O31: TRUE | P31: No | R31: Covers feeType=SPLIT + autoApprove=false (REQUESTED, awaiting approval). | S31: bao.mmo4@gmail.com | T31: 6c282544-57b6-4712-bb6a-bc696a4ee09b
B32: 23 | C32: 11 | D32: Split-cost · Approval-required · Trọng Nghĩa | E32: =$C$5+TIME(C32,0,0) | F32: =TEXT($C$5,"yyyy-mm-dd")&"T"&TEXT(C32,"00")&":00:00+07:00" | G32: 1 | H32: Badminton | I32: 10 | J32: Sân Cầu Lông Trọng Nghĩa | K32: 6 | L32: SPLIT | N32: FALSE | O32: TRUE | P32: No | R32: Covers feeType=SPLIT + autoApprove=false (REQUESTED, awaiting approval). | S32: bao.mmo8@gmail.com | T32: c98b95c9-df75-4be5-baa1-4892ed15044a
B33: 24 | C33: 11 | D33: Fixed fee (50k) · Open-join · Tin Sport | E33: =$C$5+TIME(C33,0,0) | F33: =TEXT($C$5,"yyyy-mm-dd")&"T"&TEXT(C33,"00")&":00:00+07:00" | G33: 1 | H33: Badminton | I33: 7 | J33: Tin sport Badminton (Sân cầu lông) | K33: 8 | L33: FIXED | M33: 50000 | N33: TRUE | O33: TRUE | P33: No | R33: Covers feeType=FIXED + autoApprove=true (open-join). | S33: bao.mmo6@gmail.com | T33: ebc9e657-541e-4239-b32a-feb3cab1d6c7
B34: 25 | C34: 11 | D34: Fixed fee (70k) · Open-join · Trọng Nghĩa | E34: =$C$5+TIME(C34,0,0) | F34: =TEXT($C$5,"yyyy-mm-dd")&"T"&TEXT(C34,"00")&":00:00+07:00" | G34: 1 | H34: Badminton | I34: 10 | J34: Sân Cầu Lông Trọng Nghĩa | K34: 8 | L34: FIXED | M34: 70000 | N34: TRUE | O34: TRUE | P34: No | R34: Covers feeType=FIXED + autoApprove=true (open-join). | S34: bao.mmo7@gmail.com | T34: d6e7ba31-23fa-4359-a736-e706db8284c2
B35: 26 | C35: 11 | D35: Fixed fee (50k) · Approval-required · Tin Sport | E35: =$C$5+TIME(C35,0,0) | F35: =TEXT($C$5,"yyyy-mm-dd")&"T"&TEXT(C35,"00")&":00:00+07:00" | G35: 1 | H35: Badminton | I35: 7 | J35: Tin sport Badminton (Sân cầu lông) | K35: 8 | L35: FIXED | M35: 50000 | N35: FALSE | O35: TRUE | P35: No | R35: Covers feeType=FIXED + autoApprove=false (REQUESTED, awaiting approval). | S35: bao.mmo7@gmail.com | T35: d6e7ba31-23fa-4359-a736-e706db8284c2
B36: 27 | C36: 11 | D36: Fixed fee (70k) · Approval-required · Trọng Nghĩa | E36: =$C$5+TIME(C36,0,0) | F36: =TEXT($C$5,"yyyy-mm-dd")&"T"&TEXT(C36,"00")&":00:00+07:00" | G36: 1 | H36: Badminton | I36: 10 | J36: Sân Cầu Lông Trọng Nghĩa | K36: 8 | L36: FIXED | M36: 70000 | N36: FALSE | O36: TRUE | P36: No | R36: Covers feeType=FIXED + autoApprove=false (REQUESTED, awaiting approval). | S36: bao.mmo8@gmail.com | T36: c98b95c9-df75-4be5-baa1-4892ed15044a
B37: 28 | C37: 11 | D37: Free · Open-join · Tin Sport (PRIVATE — manual DB fix) | E37: =$C$5+TIME(C37,0,0) | F37: =TEXT($C$5,"yyyy-mm-dd")&"T"&TEXT(C37,"00")&":00:00+07:00" | G37: 1 | H37: Badminton | I37: 7 | J37: Tin sport Badminton (Sân cầu lông) | K37: 10 | L37: FREE | N37: TRUE | O37: TRUE | P37: YES | Q37: UPDATE sessions SET is_public = false WHERE id = <fill in row #28's new session id after creating it via the app/API>; | R37: isPublic is hardcoded true for every standalone session at creation (SessionServiceImpl.java:225). Create via the API as normal, then run this row's Post-creation SQL against the dev DB to flip isPublic to false, and confirm GET /api/sessions/discover no longer returns it (SESSION-37/39's isPublic gate). | S37: bao.mmo8@gmail.com | T37: c98b95c9-df75-4be5-baa1-4892ed15044a
B38: 29 | C38: 11 | D38: Split-cost · Approval-required · Trọng Nghĩa (PRIVATE — manual DB fix) | E38: =$C$5+TIME(C38,0,0) | F38: =TEXT($C$5,"yyyy-mm-dd")&"T"&TEXT(C38,"00")&":00:00+07:00" | G38: 1 | H38: Badminton | I38: 10 | J38: Sân Cầu Lông Trọng Nghĩa | K38: 6 | L38: SPLIT | N38: FALSE | O38: TRUE | P38: YES | Q38: UPDATE sessions SET is_public = false WHERE id = <fill in row #29's new session id after creating it via the app/API>; | R38: isPublic is hardcoded true for every standalone session at creation (SessionServiceImpl.java:225). Create via the API as normal, then run this row's Post-creation SQL against the dev DB to flip isPublic to false, and confirm GET /api/sessions/discover no longer returns it (SESSION-37/39's isPublic gate). | S38: bao.mmo5@gmail.com | T38: 456f3ac4-98f3-43d0-9b7a-7b3bd0c886ac
B39: 30 | C39: 11 | D39: Fixed fee (50k) · Open-join · Tin Sport (PRIVATE — manual DB fix) | E39: =$C$5+TIME(C39,0,0) | F39: =TEXT($C$5,"yyyy-mm-dd")&"T"&TEXT(C39,"00")&":00:00+07:00" | G39: 1 | H39: Badminton | I39: 7 | J39: Tin sport Badminton (Sân cầu lông) | K39: 8 | L39: FIXED | M39: 50000 | N39: TRUE | O39: TRUE | P39: YES | Q39: UPDATE sessions SET is_public = false WHERE id = <fill in row #30's new session id after creating it via the app/API>; | R39: isPublic is hardcoded true for every standalone session at creation (SessionServiceImpl.java:225). Create via the API as normal, then run this row's Post-creation SQL against the dev DB to flip isPublic to false, and confirm GET /api/sessions/discover no longer returns it (SESSION-37/39's isPublic gate). | S39: bao.mmo6@gmail.com | T39: ebc9e657-541e-4239-b32a-feb3cab1d6c7
B40: 31 | C40: 15 | D40: Free · Open-join · Tin Sport | E40: =$C$5+TIME(C40,0,0) | F40: =TEXT($C$5,"yyyy-mm-dd")&"T"&TEXT(C40,"00")&":00:00+07:00" | G40: 1 | H40: Badminton | I40: 7 | J40: Tin sport Badminton (Sân cầu lông) | K40: 10 | L40: FREE | N40: TRUE | O40: TRUE | P40: No | R40: Covers feeType=FREE + autoApprove=true (open-join). | S40: bao.mmo8@gmail.com | T40: c98b95c9-df75-4be5-baa1-4892ed15044a
B41: 32 | C41: 15 | D41: Free · Open-join · Trọng Nghĩa | E41: =$C$5+TIME(C41,0,0) | F41: =TEXT($C$5,"yyyy-mm-dd")&"T"&TEXT(C41,"00")&":00:00+07:00" | G41: 1 | H41: Badminton | I41: 10 | J41: Sân Cầu Lông Trọng Nghĩa | K41: 10 | L41: FREE | N41: TRUE | O41: TRUE | P41: No | R41: Covers feeType=FREE + autoApprove=true (open-join). | S41: bao.mmo4@gmail.com | T41: 6c282544-57b6-4712-bb6a-bc696a4ee09b
B42: 33 | C42: 15 | D42: Free · Approval-required · Tin Sport | E42: =$C$5+TIME(C42,0,0) | F42: =TEXT($C$5,"yyyy-mm-dd")&"T"&TEXT(C42,"00")&":00:00+07:00" | G42: 1 | H42: Badminton | I42: 7 | J42: Tin sport Badminton (Sân cầu lông) | K42: 10 | L42: FREE | N42: FALSE | O42: TRUE | P42: No | R42: Covers feeType=FREE + autoApprove=false (REQUESTED, awaiting approval). | S42: bao.mmo3@gmail.com | T42: a4989bbe-033a-4a20-9784-7dafe8a7829e
B43: 34 | C43: 15 | D43: Free · Approval-required · Trọng Nghĩa | E43: =$C$5+TIME(C43,0,0) | F43: =TEXT($C$5,"yyyy-mm-dd")&"T"&TEXT(C43,"00")&":00:00+07:00" | G43: 1 | H43: Badminton | I43: 10 | J43: Sân Cầu Lông Trọng Nghĩa | K43: 10 | L43: FREE | N43: FALSE | O43: TRUE | P43: No | R43: Covers feeType=FREE + autoApprove=false (REQUESTED, awaiting approval). | S43: bao.mmo5@gmail.com | T43: 456f3ac4-98f3-43d0-9b7a-7b3bd0c886ac
B44: 35 | C44: 15 | D44: Split-cost · Open-join · Tin Sport | E44: =$C$5+TIME(C44,0,0) | F44: =TEXT($C$5,"yyyy-mm-dd")&"T"&TEXT(C44,"00")&":00:00+07:00" | G44: 1 | H44: Badminton | I44: 7 | J44: Tin sport Badminton (Sân cầu lông) | K44: 6 | L44: SPLIT | N44: TRUE | O44: TRUE | P44: No | R44: Covers feeType=SPLIT + autoApprove=true (open-join). | S44: bao.mmo4@gmail.com | T44: 6c282544-57b6-4712-bb6a-bc696a4ee09b
...

Sheet Summary
B2: Coverage summary (live formulas against the Session Generator tab)
B4: Total sessions | C4: =COUNTA('Session Generator'!B10:B84)
B6: By hour slot
B7: 07:00 | C7: =COUNTIF('Session Generator'!C10:C84,7)
B8: 11:00 | C8: =COUNTIF('Session Generator'!C10:C84,11)
B9: 15:00 | C9: =COUNTIF('Session Generator'!C10:C84,15)
B10: 19:00 | C10: =COUNTIF('Session Generator'!C10:C84,19)
B11: 23:00 | C11: =COUNTIF('Session Generator'!C10:C84,23)
B13: By feeType
B14: FREE | C14: =COUNTIF('Session Generator'!L10:L84,"FREE")
B15: SPLIT | C15: =COUNTIF('Session Generator'!L10:L84,"SPLIT")
B16: FIXED | C16: =COUNTIF('Session Generator'!L10:L84,"FIXED")
B18: By autoApprove
B19: TRUE (open-join) | C19: =COUNTIF('Session Generator'!N10:N84,"TRUE")
B20: FALSE (approval-required) | C20: =COUNTIF('Session Generator'!N10:N84,"FALSE")
B22: Private-test rows (manual DB fix) | C22: =COUNTIF('Session Generator'!P10:P84,"YES")
B23: By location
B24: Tin Sport (id 7) | C24: =COUNTIF('Session Generator'!I10:I84,7)
B25: Trọng Nghĩa (id 10) | C25: =COUNTIF('Session Generator'!I10:I84,10)
B27: By author
B28: bao.mmo3@gmail.com | C28: =COUNTIF('Session Generator'!T10:T84,"a4989bbe-033a-4a20-9784-7dafe8a7829e")
B29: bao.mmo4@gmail.com | C29: =COUNTIF('Session Generator'!T10:T84,"6c282544-57b6-4712-bb6a-bc696a4ee09b")
B30: bao.mmo5@gmail.com | C30: =COUNTIF('Session Generator'!T10:T84,"456f3ac4-98f3-43d0-9b7a-7b3bd0c886ac")
B31: bao.mmo6@gmail.com | C31: =COUNTIF('Session Generator'!T10:T84,"ebc9e657-541e-4239-b32a-feb3cab1d6c7")
B32: bao.mmo7@gmail.com | C32: =COUNTIF('Session Generator'!T10:T84,"d6e7ba31-23fa-4359-a736-e706db8284c2")
B33: bao.mmo8@gmail.com | C33: =COUNTIF('Session Generator'!T10:T84,"c98b95c9-df75-4be5-baa1-4892ed15044a")

Sheet Locations (Badminton, real DB)
B2: Badminton (sportId 1) locations — sportconnect_dev, queried 2026-09-23
B3: Pulled live via `docker exec sportconnect-dev-postgres-1 psql ... SELECT id, name, address, timezone FROM locations WHERE sport_id = 1`. The 2 rows marked ★ look like genuine data; the other 6 are named like test fixtures and are listed for completeness only — not used above.
B5: id | C5: name | D5: address | E5: timezone | F5: used above?
B6: 2 | C6: LOC2 Test Court | D6: 123 Test St | F6: No — test fixture
B7: 3 | C7: Discover Test Court | F7: No — test fixture
B8: 4 | C8: Fee Test Court | F8: No — test fixture
B9: 5 | C9: Approval Test Court | F9: No — test fixture
B10: 7 | C10: Tin sport Badminton (Sân cầu lông) | E10: Asia/Ho_Chi_Minh | F10: ★ Yes
B11: 8 | C11: SESSION-15 Test Court | D11: 123 Test St | E11: Asia/Ho_Chi_Minh | F11: No — test fixture
B12: 9 | C12: NTF-2 Test Court | D12: 456 Test Ave | E12: Asia/Ho_Chi_Minh | F12: No — test fixture
B13: 10 | C13: Sân Cầu Lông Trọng Nghĩa | E13: Asia/Ho_Chi_Minh | F13: ★ Yes

Sheet Authors (bao.mmo, real DB)
B2: Users matching email ILIKE 'bao.mmo%' — sportconnect_dev, queried 2026-09-23
B3: One of these 6 real, active users is randomly assigned as each row's author on the Session Generator tab (assigned once at generation time, not re-randomized on open — see Read Me). "Times used" is a live count against that tab.
B5: email | C5: name | D5: userId | E5: times used above
B6: bao.mmo3@gmail.com | C6: Bao Nguyen | D6: a4989bbe-033a-4a20-9784-7dafe8a7829e | E6: =COUNTIF('Session Generator'!T10:T84,"a4989bbe-033a-4a20-9784-7dafe8a7829e")
B7: bao.mmo4@gmail.com | C7: Bao Nguyen 4 | D7: 6c282544-57b6-4712-bb6a-bc696a4ee09b | E7: =COUNTIF('Session Generator'!T10:T84,"6c282544-57b6-4712-bb6a-bc696a4ee09b")
B8: bao.mmo5@gmail.com | C8: bao 5 | D8: 456f3ac4-98f3-43d0-9b7a-7b3bd0c886ac | E8: =COUNTIF('Session Generator'!T10:T84,"456f3ac4-98f3-43d0-9b7a-7b3bd0c886ac")
B9: bao.mmo6@gmail.com | C9: bao 6 | D9: ebc9e657-541e-4239-b32a-feb3cab1d6c7 | E9: =COUNTIF('Session Generator'!T10:T84,"ebc9e657-541e-4239-b32a-feb3cab1d6c7")
B10: bao.mmo7@gmail.com | C10: bao 7 | D10: d6e7ba31-23fa-4359-a736-e706db8284c2 | E10: =COUNTIF('Session Generator'!T10:T84,"d6e7ba31-23fa-4359-a736-e706db8284c2")
B11: bao.mmo8@gmail.com | C11: bao 8 | D11: c98b95c9-df75-4be5-baa1-4892ed15044a | E11: =COUNTIF('Session Generator'!T10:T84,"c98b95c9-df75-4be5-baa1-4892ed15044a")

Sheet Read Me
B2: Read Me — assumptions, decisions, and known gaps
B4: Purpose | C4: Test-data prep for 75 standalone Badminton session cases (15 per hour slot × 5 hour slots) covering the fields Discover/join-flow logic branches on, for a single input date.
B6: The 15-case template | C6: 12 public combos = 3 feeType (FREE/SPLIT/FIXED) × 2 autoApprove (TRUE/FALSE) × 2 real locations — every combination exactly once. + 3 "private test" duplicates (one FREE, one SPLIT, one FIXED case, each in one of the 2 locations) that additionally need the manual DB fix described below. This exact same 15-case template repeats at each of the 5 hour slots, so every hour has full coverage — useful for testing Discover's startTimeFilter/startTime against every case at every hour.
B8: Author (createdBy) | C8: Randomly assigned per row from the 6 real, active sportconnect_dev users matching email ILIKE 'bao.mmo%' (see the Authors tab) — assigned once when this file was generated, written as a fixed value like every other case-design column (title, feeType, capacity, etc.), not a live/volatile formula that would reshuffle every time you reopen the file or edit the date cell. IMPORTANT: CreateSessionRequest has no createdBy field — the creator is always derived server-side from the caller's own JWT (SecurityUtils.extractUserId), never the request body. "Author userId" here means: to create this row's session exactly as designed, you must be authenticated as that user (i.e. hold that user's access token) when calling POST /api/sessions — it is not something you paste into the payload.
B10: Why no VBA "Generate" button | C10: A real macro button could not be executed/verified in the environment this file was built in (no local Python or LibreOffice install to test-recalculate against), so it is deliberately left out. Every row's Scheduled Start recalculates the instant you change the date cell on the Generator tab — same practical effect, no macro-security prompt on open, opens identically in Excel/LibreOffice/Google Sheets.
B12: Not independently recalculated before delivery | C12: This file was built with the exceljs library (no local Python/openpyxl or LibreOffice available on this machine to auto-verify formulas), so please sanity-check the Scheduled Start columns and the Summary/Authors tabs' counts render correctly the first time you open it and change the date.
B14: Row grouping | C14: Every data row has outline level 1 (grouped per contiguous hour block) — use the ± controls in the sheet's left margin to collapse/expand an hour's 15 rows at a time.
B16: Hours | C16: Fixed at 07:00, 11:00, 15:00, 19:00, 23:00 — evenly spread across the requested 07:00–23:00 window.
B18: "Private/public" | C18: Session has no client-settable private/public field. isPublic exists on the entity but SessionServiceImpl.java:225 hardcodes it to (groupId == null) at creation — every standalone session is isPublic=true, unconditionally, with no create/update endpoint field to override it (verified against CreateSessionRequest.java and UpdateSessionRequest.java — neither declares it). The 15 rows per day flagged "Manual DB fix needed = YES" (3 per hour) are the exception this sheet builds for: create each normally via the app/API, then run its own Post-creation SQL cell directly against the dev DB to flip isPublic to false, and confirm GET /api/sessions/discover's isPublic gate (SESSION-37/39) excludes it.
B20: autoApprove as the closest real "approval gate" | C20: TRUE = anyone can join instantly. FALSE = a non-invited joiner lands in REQUESTED, awaiting the creator's approval (session.ts's own ParticipantStatus doc comment).
B22: Locations | C22: Both used locations (ids 7 and 10) are real sportconnect_dev rows for sportId=1 (Badminton), not fixtures — see the Locations tab. Their timezone is Asia/Ho_Chi_Minh (UTC+7), which is why the API payload column hardcodes a +07:00 offset. Each combo appears with each location, splitting the 12 public rows per hour 6/6 between them.
B24: scheduledStart contract | C24: CreateSessionRequest.scheduledStart is a required, offset-aware Instant (SESSION-33) — an offset-less string is rejected with a 400. The "API payload" column already includes +07:00; paste it into the request body as-is.
B26: feeAmountVnd | C26: Populated only for FIXED rows (meaningful only when feeType=FIXED per FeeType's own doc comment in shared/types/session.ts) — left blank for FREE/SPLIT rows. Fixed at 50,000 VND for location id 7 and 70,000 VND for location id 10 (placeholder round numbers, not sourced from real pricing data) — change them if you need a specific figure.
... B32: Not covered by this sheet | C32: PREPARING-status sessions (omitted locationId/feeType), group-linked sessions, inviteeIds, and session attributes — all out of scope for this standalone-session test-data request.
